<?xml version="1.0"?>
<robot name="myscara">

  <link name="base_link">
    <visual>
      <geometry>
        <cylinder length="0.6" radius="0.2"/>
      </geometry>
    </visual>
  </link>

  <link name="link1">
    <visual>
      <geometry>
        <box size="3 0.6 0.6"/>
      </geometry>
    </visual>
  </link>

   <joint name="base_to_link1" type="revolute">
       <origin xyz="0 0 1.2" rpy = "0 0 0"/>
       <limit effort = "1000.0" lower="0.0" upper="3.14" velocity="0.5"/>
       <axis xyz="0 0 1" />
       <parent link="base_link"/>
       <child link="link1"/>
  </joint>
</robot>